2018-07-17 15:14:04,024 INFO: Microblog startup [in /storage/emulated/0/Download/blog/app/__init__.py:33]
2018-07-17 15:14:22,047 ERROR: Exception on / [GET] [in /data/user/0/ru.iiec.pydroid3/files/arm-linux-androideabi/lib/python3.6/site-packages/flask/app.py:1761]
Traceback (most recent call last):
  File "/data/user/0/ru.iiec.pydroid3/files/arm-linux-androideabi/lib/python3.6/site-packages/flask/app.py", line 2292, in wsgi_app
    response = self.full_dispatch_request()
  File "/data/user/0/ru.iiec.pydroid3/files/arm-linux-androideabi/lib/python3.6/site-packages/flask/app.py", line 1815, in full_dispatch_request
    rv = self.handle_user_exception(e)
  File "/data/user/0/ru.iiec.pydroid3/files/arm-linux-androideabi/lib/python3.6/site-packages/flask/app.py", line 1718, in handle_user_exception
    reraise(exc_type, exc_value, tb)
  File "/data/user/0/ru.iiec.pydroid3/files/arm-linux-androideabi/lib/python3.6/site-packages/flask/_compat.py", line 35, in reraise
    raise value
  File "/data/user/0/ru.iiec.pydroid3/files/arm-linux-androideabi/lib/python3.6/site-packages/flask/app.py", line 1813, in full_dispatch_request
    rv = self.dispatch_request()
  File "/data/user/0/ru.iiec.pydroid3/files/arm-linux-androideabi/lib/python3.6/site-packages/flask/app.py", line 1799, in dispatch_request
    return self.view_functions[rule.endpoint](**req.view_args)
  File "/data/user/0/ru.iiec.pydroid3/files/arm-linux-androideabi/lib/python3.6/site-packages/flask_login/utils.py", line 261, in decorated_view
    return func(*args, **kwargs)
  File "/storage/emulated/0/Download/blog/app/routers.py", line 15, in index
    form = PostForm()
  File "/data/user/0/ru.iiec.pydroid3/files/arm-linux-androideabi/lib/python3.6/site-packages/wtforms/form.py", line 212, in __call__
    return type.__call__(cls, *args, **kwargs)
  File "/data/user/0/ru.iiec.pydroid3/files/arm-linux-androideabi/lib/python3.6/site-packages/flask_wtf/form.py", line 88, in __init__
    super(FlaskForm, self).__init__(formdata=formdata, **kwargs)
  File "/data/user/0/ru.iiec.pydroid3/files/arm-linux-androideabi/lib/python3.6/site-packages/wtforms/form.py", line 272, in __init__
    super(Form, self).__init__(self._unbound_fields, meta=meta_obj, prefix=prefix)
  File "/data/user/0/ru.iiec.pydroid3/files/arm-linux-androideabi/lib/python3.6/site-packages/wtforms/form.py", line 52, in __init__
    field = meta.bind_field(self, unbound_field, options)
  File "/data/user/0/ru.iiec.pydroid3/files/arm-linux-androideabi/lib/python3.6/site-packages/wtforms/meta.py", line 27, in bind_field
    return unbound_field.bind(form=form, **options)
  File "/data/user/0/ru.iiec.pydroid3/files/arm-linux-androideabi/lib/python3.6/site-packages/wtforms/fields/core.py", line 353, in bind
    return self.field_class(*self.args, **kw)
TypeError: __init__() got an unexpected keyword argument 'valudators'
2018-07-17 15:14:54,198 INFO: Microblog startup [in /storage/emulated/0/Download/blog/app/__init__.py:33]
2018-07-17 15:14:59,388 ERROR: Exception on / [GET] [in /data/user/0/ru.iiec.pydroid3/files/arm-linux-androideabi/lib/python3.6/site-packages/flask/app.py:1761]
Traceback (most recent call last):
  File "/data/user/0/ru.iiec.pydroid3/files/arm-linux-androideabi/lib/python3.6/site-packages/flask/app.py", line 2292, in wsgi_app
    response = self.full_dispatch_request()
  File "/data/user/0/ru.iiec.pydroid3/files/arm-linux-androideabi/lib/python3.6/site-packages/flask/app.py", line 1815, in full_dispatch_request
    rv = self.handle_user_exception(e)
  File "/data/user/0/ru.iiec.pydroid3/files/arm-linux-androideabi/lib/python3.6/site-packages/flask/app.py", line 1718, in handle_user_exception
    reraise(exc_type, exc_value, tb)
  File "/data/user/0/ru.iiec.pydroid3/files/arm-linux-androideabi/lib/python3.6/site-packages/flask/_compat.py", line 35, in reraise
    raise value
  File "/data/user/0/ru.iiec.pydroid3/files/arm-linux-androideabi/lib/python3.6/site-packages/flask/app.py", line 1813, in full_dispatch_request
    rv = self.dispatch_request()
  File "/data/user/0/ru.iiec.pydroid3/files/arm-linux-androideabi/lib/python3.6/site-packages/flask/app.py", line 1799, in dispatch_request
    return self.view_functions[rule.endpoint](**req.view_args)
  File "/data/user/0/ru.iiec.pydroid3/files/arm-linux-androideabi/lib/python3.6/site-packages/flask_login/utils.py", line 261, in decorated_view
    return func(*args, **kwargs)
  File "/storage/emulated/0/Download/blog/app/routers.py", line 16, in index
    if form.valudate_on_dubmit():
AttributeError: 'PostForm' object has no attribute 'valudate_on_dubmit'
2018-07-17 15:15:22,023 INFO: Microblog startup [in /storage/emulated/0/Download/blog/app/__init__.py:33]
2018-07-17 15:15:24,586 ERROR: Exception on / [GET] [in /data/user/0/ru.iiec.pydroid3/files/arm-linux-androideabi/lib/python3.6/site-packages/flask/app.py:1761]
Traceback (most recent call last):
  File "/data/user/0/ru.iiec.pydroid3/files/arm-linux-androideabi/lib/python3.6/site-packages/flask/app.py", line 2292, in wsgi_app
    response = self.full_dispatch_request()
  File "/data/user/0/ru.iiec.pydroid3/files/arm-linux-androideabi/lib/python3.6/site-packages/flask/app.py", line 1815, in full_dispatch_request
    rv = self.handle_user_exception(e)
  File "/data/user/0/ru.iiec.pydroid3/files/arm-linux-androideabi/lib/python3.6/site-packages/flask/app.py", line 1718, in handle_user_exception
    reraise(exc_type, exc_value, tb)
  File "/data/user/0/ru.iiec.pydroid3/files/arm-linux-androideabi/lib/python3.6/site-packages/flask/_compat.py", line 35, in reraise
    raise value
  File "/data/user/0/ru.iiec.pydroid3/files/arm-linux-androideabi/lib/python3.6/site-packages/flask/app.py", line 1813, in full_dispatch_request
    rv = self.dispatch_request()
  File "/data/user/0/ru.iiec.pydroid3/files/arm-linux-androideabi/lib/python3.6/site-packages/flask/app.py", line 1799, in dispatch_request
    return self.view_functions[rule.endpoint](**req.view_args)
  File "/data/user/0/ru.iiec.pydroid3/files/arm-linux-androideabi/lib/python3.6/site-packages/flask_login/utils.py", line 261, in decorated_view
    return func(*args, **kwargs)
  File "/storage/emulated/0/Download/blog/app/routers.py", line 16, in index
    if form.validate_on_dubmit():
AttributeError: 'PostForm' object has no attribute 'validate_on_dubmit'
2018-07-17 15:15:41,634 INFO: Microblog startup [in /storage/emulated/0/Download/blog/app/__init__.py:33]
2018-07-17 15:15:44,838 ERROR: Exception on / [GET] [in /data/user/0/ru.iiec.pydroid3/files/arm-linux-androideabi/lib/python3.6/site-packages/flask/app.py:1761]
Traceback (most recent call last):
  File "/data/user/0/ru.iiec.pydroid3/files/arm-linux-androideabi/lib/python3.6/site-packages/flask/app.py", line 2292, in wsgi_app
    response = self.full_dispatch_request()
  File "/data/user/0/ru.iiec.pydroid3/files/arm-linux-androideabi/lib/python3.6/site-packages/flask/app.py", line 1815, in full_dispatch_request
    rv = self.handle_user_exception(e)
  File "/data/user/0/ru.iiec.pydroid3/files/arm-linux-androideabi/lib/python3.6/site-packages/flask/app.py", line 1718, in handle_user_exception
    reraise(exc_type, exc_value, tb)
  File "/data/user/0/ru.iiec.pydroid3/files/arm-linux-androideabi/lib/python3.6/site-packages/flask/_compat.py", line 35, in reraise
    raise value
  File "/data/user/0/ru.iiec.pydroid3/files/arm-linux-androideabi/lib/python3.6/site-packages/flask/app.py", line 1813, in full_dispatch_request
    rv = self.dispatch_request()
  File "/data/user/0/ru.iiec.pydroid3/files/arm-linux-androideabi/lib/python3.6/site-packages/flask/app.py", line 1799, in dispatch_request
    return self.view_functions[rule.endpoint](**req.view_args)
  File "/data/user/0/ru.iiec.pydroid3/files/arm-linux-androideabi/lib/python3.6/site-packages/flask_login/utils.py", line 261, in decorated_view
    return func(*args, **kwargs)
  File "/storage/emulated/0/Download/blog/app/routers.py", line 22, in index
    posts = current_user.followed_posts().all()
  File "/data/user/0/ru.iiec.pydroid3/files/arm-linux-androideabi/lib/python3.6/site-packages/werkzeug/local.py", line 347, in __getattr__
    return getattr(self._get_current_object(), name)
AttributeError: 'User' object has no attribute 'followed_posts'
2018-07-17 15:16:11,591 INFO: Microblog startup [in /storage/emulated/0/Download/blog/app/__init__.py:33]
2018-07-17 15:16:14,776 ERROR: Exception on / [GET] [in /data/user/0/ru.iiec.pydroid3/files/arm-linux-androideabi/lib/python3.6/site-packages/flask/app.py:1761]
Traceback (most recent call last):
  File "/data/user/0/ru.iiec.pydroid3/files/arm-linux-androideabi/lib/python3.6/site-packages/flask/app.py", line 2292, in wsgi_app
    response = self.full_dispatch_request()
  File "/data/user/0/ru.iiec.pydroid3/files/arm-linux-androideabi/lib/python3.6/site-packages/flask/app.py", line 1815, in full_dispatch_request
    rv = self.handle_user_exception(e)
  File "/data/user/0/ru.iiec.pydroid3/files/arm-linux-androideabi/lib/python3.6/site-packages/flask/app.py", line 1718, in handle_user_exception
    reraise(exc_type, exc_value, tb)
  File "/data/user/0/ru.iiec.pydroid3/files/arm-linux-androideabi/lib/python3.6/site-packages/flask/_compat.py", line 35, in reraise
    raise value
  File "/data/user/0/ru.iiec.pydroid3/files/arm-linux-androideabi/lib/python3.6/site-packages/flask/app.py", line 1813, in full_dispatch_request
    rv = self.dispatch_request()
  File "/data/user/0/ru.iiec.pydroid3/files/arm-linux-androideabi/lib/python3.6/site-packages/flask/app.py", line 1799, in dispatch_request
    return self.view_functions[rule.endpoint](**req.view_args)
  File "/data/user/0/ru.iiec.pydroid3/files/arm-linux-androideabi/lib/python3.6/site-packages/flask_login/utils.py", line 261, in decorated_view
    return func(*args, **kwargs)
  File "/storage/emulated/0/Download/blog/app/routers.py", line 22, in index
    posts = current_user.followed_post().all()
  File "/storage/emulated/0/Download/blog/app/models.py", line 62, in followed_post
    own = Post.query.filter_by(user_id == self.id)
NameError: name 'user_id' is not defined
