2018-07-12 16:18:33,342 ERROR: Exception on /user/Billy [GET] [in /data/user/0/ru.iiec.pydroid3/files/arm-linux-androideabi/lib/python3.6/site-packages/flask/app.py:1761]
Traceback (most recent call last):
  File "/data/user/0/ru.iiec.pydroid3/files/arm-linux-androideabi/lib/python3.6/site-packages/flask/app.py", line 2292, in wsgi_app
    response = self.full_dispatch_request()
  File "/data/user/0/ru.iiec.pydroid3/files/arm-linux-androideabi/lib/python3.6/site-packages/flask/app.py", line 1815, in full_dispatch_request
    rv = self.handle_user_exception(e)
  File "/data/user/0/ru.iiec.pydroid3/files/arm-linux-androideabi/lib/python3.6/site-packages/flask/app.py", line 1718, in handle_user_exception
    reraise(exc_type, exc_value, tb)
  File "/data/user/0/ru.iiec.pydroid3/files/arm-linux-androideabi/lib/python3.6/site-packages/flask/_compat.py", line 35, in reraise
    raise value
  File "/data/user/0/ru.iiec.pydroid3/files/arm-linux-androideabi/lib/python3.6/site-packages/flask/app.py", line 1813, in full_dispatch_request
    rv = self.dispatch_request()
  File "/data/user/0/ru.iiec.pydroid3/files/arm-linux-androideabi/lib/python3.6/site-packages/flask/app.py", line 1799, in dispatch_request
    return self.view_functions[rule.endpoint](**req.view_args)
  File "/data/user/0/ru.iiec.pydroid3/files/arm-linux-androideabi/lib/python3.6/site-packages/flask_login/utils.py", line 261, in decorated_view
    return func(*args, **kwargs)
  File "/storage/emulated/0/Download/blog/app/routers.py", line 37, in user
    return render_template('user.html', user=user, posts=posts)
  File "/data/user/0/ru.iiec.pydroid3/files/arm-linux-androideabi/lib/python3.6/site-packages/flask/templating.py", line 135, in render_template
    context, ctx.app)
  File "/data/user/0/ru.iiec.pydroid3/files/arm-linux-androideabi/lib/python3.6/site-packages/flask/templating.py", line 117, in _render
    rv = template.render(context)
  File "/data/user/0/ru.iiec.pydroid3/files/arm-linux-androideabi/lib/python3.6/site-packages/jinja2/asyncsupport.py", line 76, in render
    return original_render(self, *args, **kwargs)
  File "/data/user/0/ru.iiec.pydroid3/files/arm-linux-androideabi/lib/python3.6/site-packages/jinja2/environment.py", line 1008, in render
    return self.environment.handle_exception(exc_info, True)
  File "/data/user/0/ru.iiec.pydroid3/files/arm-linux-androideabi/lib/python3.6/site-packages/jinja2/environment.py", line 780, in handle_exception
    reraise(exc_type, exc_value, tb)
  File "/data/user/0/ru.iiec.pydroid3/files/arm-linux-androideabi/lib/python3.6/site-packages/jinja2/_compat.py", line 37, in reraise
    raise value.with_traceback(tb)
  File "/storage/emulated/0/Download/blog/app/templates/user.html", line 1, in top-level template code
    {% extends "base.html" %}
  File "/storage/emulated/0/Download/blog/app/templates/base.html", line 31, in top-level template code
    {% block content%}
  File "/storage/emulated/0/Download/blog/app/templates/user.html", line 15, in block "content"
    <p>{{ user.followers.count() }} followers, {{ user.followed.count() }} following.</p>
TypeError: count() takes exactly one argument (0 given)
2018-07-12 16:22:38,299 INFO: Microblog startup [in /storage/emulated/0/Download/blog/app/__init__.py:33]
2018-07-12 16:22:53,441 ERROR: Exception on /user/Billy [GET] [in /data/user/0/ru.iiec.pydroid3/files/arm-linux-androideabi/lib/python3.6/site-packages/flask/app.py:1761]
Traceback (most recent call last):
  File "/data/user/0/ru.iiec.pydroid3/files/arm-linux-androideabi/lib/python3.6/site-packages/flask/app.py", line 2292, in wsgi_app
    response = self.full_dispatch_request()
  File "/data/user/0/ru.iiec.pydroid3/files/arm-linux-androideabi/lib/python3.6/site-packages/flask/app.py", line 1815, in full_dispatch_request
    rv = self.handle_user_exception(e)
  File "/data/user/0/ru.iiec.pydroid3/files/arm-linux-androideabi/lib/python3.6/site-packages/flask/app.py", line 1718, in handle_user_exception
    reraise(exc_type, exc_value, tb)
  File "/data/user/0/ru.iiec.pydroid3/files/arm-linux-androideabi/lib/python3.6/site-packages/flask/_compat.py", line 35, in reraise
    raise value
  File "/data/user/0/ru.iiec.pydroid3/files/arm-linux-androideabi/lib/python3.6/site-packages/flask/app.py", line 1813, in full_dispatch_request
    rv = self.dispatch_request()
  File "/data/user/0/ru.iiec.pydroid3/files/arm-linux-androideabi/lib/python3.6/site-packages/flask/app.py", line 1799, in dispatch_request
    return self.view_functions[rule.endpoint](**req.view_args)
  File "/data/user/0/ru.iiec.pydroid3/files/arm-linux-androideabi/lib/python3.6/site-packages/flask_login/utils.py", line 261, in decorated_view
    return func(*args, **kwargs)
  File "/storage/emulated/0/Download/blog/app/routers.py", line 37, in user
    return render_template('user.html', user=user, posts=posts)
  File "/data/user/0/ru.iiec.pydroid3/files/arm-linux-androideabi/lib/python3.6/site-packages/flask/templating.py", line 135, in render_template
    context, ctx.app)
  File "/data/user/0/ru.iiec.pydroid3/files/arm-linux-androideabi/lib/python3.6/site-packages/flask/templating.py", line 117, in _render
    rv = template.render(context)
  File "/data/user/0/ru.iiec.pydroid3/files/arm-linux-androideabi/lib/python3.6/site-packages/jinja2/asyncsupport.py", line 76, in render
    return original_render(self, *args, **kwargs)
  File "/data/user/0/ru.iiec.pydroid3/files/arm-linux-androideabi/lib/python3.6/site-packages/jinja2/environment.py", line 1008, in render
    return self.environment.handle_exception(exc_info, True)
  File "/data/user/0/ru.iiec.pydroid3/files/arm-linux-androideabi/lib/python3.6/site-packages/jinja2/environment.py", line 780, in handle_exception
    reraise(exc_type, exc_value, tb)
  File "/data/user/0/ru.iiec.pydroid3/files/arm-linux-androideabi/lib/python3.6/site-packages/jinja2/_compat.py", line 37, in reraise
    raise value.with_traceback(tb)
  File "/storage/emulated/0/Download/blog/app/templates/user.html", line 1, in top-level template code
    {% extends "base.html" %}
  File "/storage/emulated/0/Download/blog/app/templates/base.html", line 31, in top-level template code
    {% block content%}
  File "/storage/emulated/0/Download/blog/app/templates/user.html", line 15, in block "content"
    <p>{{ user.followers.count() }} followers, {{ user.followed.count() }} following.</p>
TypeError: count() takes exactly one argument (0 given)
2018-07-12 16:24:00,444 INFO: Microblog startup [in /storage/emulated/0/Download/blog/app/__init__.py:33]
2018-07-12 16:24:10,645 ERROR: Exception on /user/Billy [GET] [in /data/user/0/ru.iiec.pydroid3/files/arm-linux-androideabi/lib/python3.6/site-packages/flask/app.py:1761]
Traceback (most recent call last):
  File "/data/user/0/ru.iiec.pydroid3/files/arm-linux-androideabi/lib/python3.6/site-packages/flask/app.py", line 2292, in wsgi_app
    response = self.full_dispatch_request()
  File "/data/user/0/ru.iiec.pydroid3/files/arm-linux-androideabi/lib/python3.6/site-packages/flask/app.py", line 1815, in full_dispatch_request
    rv = self.handle_user_exception(e)
  File "/data/user/0/ru.iiec.pydroid3/files/arm-linux-androideabi/lib/python3.6/site-packages/flask/app.py", line 1718, in handle_user_exception
    reraise(exc_type, exc_value, tb)
  File "/data/user/0/ru.iiec.pydroid3/files/arm-linux-androideabi/lib/python3.6/site-packages/flask/_compat.py", line 35, in reraise
    raise value
  File "/data/user/0/ru.iiec.pydroid3/files/arm-linux-androideabi/lib/python3.6/site-packages/flask/app.py", line 1813, in full_dispatch_request
    rv = self.dispatch_request()
  File "/data/user/0/ru.iiec.pydroid3/files/arm-linux-androideabi/lib/python3.6/site-packages/flask/app.py", line 1799, in dispatch_request
    return self.view_functions[rule.endpoint](**req.view_args)
  File "/data/user/0/ru.iiec.pydroid3/files/arm-linux-androideabi/lib/python3.6/site-packages/flask_login/utils.py", line 261, in decorated_view
    return func(*args, **kwargs)
  File "/storage/emulated/0/Download/blog/app/routers.py", line 37, in user
    return render_template('user.html', user=user, posts=posts)
  File "/data/user/0/ru.iiec.pydroid3/files/arm-linux-androideabi/lib/python3.6/site-packages/flask/templating.py", line 135, in render_template
    context, ctx.app)
  File "/data/user/0/ru.iiec.pydroid3/files/arm-linux-androideabi/lib/python3.6/site-packages/flask/templating.py", line 117, in _render
    rv = template.render(context)
  File "/data/user/0/ru.iiec.pydroid3/files/arm-linux-androideabi/lib/python3.6/site-packages/jinja2/asyncsupport.py", line 76, in render
    return original_render(self, *args, **kwargs)
  File "/data/user/0/ru.iiec.pydroid3/files/arm-linux-androideabi/lib/python3.6/site-packages/jinja2/environment.py", line 1008, in render
    return self.environment.handle_exception(exc_info, True)
  File "/data/user/0/ru.iiec.pydroid3/files/arm-linux-androideabi/lib/python3.6/site-packages/jinja2/environment.py", line 780, in handle_exception
    reraise(exc_type, exc_value, tb)
  File "/data/user/0/ru.iiec.pydroid3/files/arm-linux-androideabi/lib/python3.6/site-packages/jinja2/_compat.py", line 37, in reraise
    raise value.with_traceback(tb)
  File "/storage/emulated/0/Download/blog/app/templates/user.html", line 1, in top-level template code
    {% extends "base.html" %}
  File "/storage/emulated/0/Download/blog/app/templates/base.html", line 31, in top-level template code
    {% block content%}
  File "/storage/emulated/0/Download/blog/app/templates/user.html", line 15, in block "content"
    <p>{{ user.followers.count() }} followers, {{ user.followed.count() }} following.</p>
TypeError: count() takes exactly one argument (0 given)
