2018-07-12 17:25:15,515 ERROR: Exception on /follow/nelly [GET] [in /data/user/0/ru.iiec.pydroid3/files/arm-linux-androideabi/lib/python3.6/site-packages/flask/app.py:1761]
Traceback (most recent call last):
  File "/data/user/0/ru.iiec.pydroid3/files/arm-linux-androideabi/lib/python3.6/site-packages/sqlalchemy/engine/base.py", line 1193, in _execute_context
    context)
  File "/data/user/0/ru.iiec.pydroid3/files/arm-linux-androideabi/lib/python3.6/site-packages/sqlalchemy/engine/default.py", line 508, in do_execute
    cursor.execute(statement, parameters)
sqlite3.OperationalError: only a single result allowed for a SELECT that is part of an expression

The above exception was the direct cause of the following exception:

Traceback (most recent call last):
  File "/data/user/0/ru.iiec.pydroid3/files/arm-linux-androideabi/lib/python3.6/site-packages/flask/app.py", line 2292, in wsgi_app
    response = self.full_dispatch_request()
  File "/data/user/0/ru.iiec.pydroid3/files/arm-linux-androideabi/lib/python3.6/site-packages/flask/app.py", line 1815, in full_dispatch_request
    rv = self.handle_user_exception(e)
  File "/data/user/0/ru.iiec.pydroid3/files/arm-linux-androideabi/lib/python3.6/site-packages/flask/app.py", line 1718, in handle_user_exception
    reraise(exc_type, exc_value, tb)
  File "/data/user/0/ru.iiec.pydroid3/files/arm-linux-androideabi/lib/python3.6/site-packages/flask/_compat.py", line 35, in reraise
    raise value
  File "/data/user/0/ru.iiec.pydroid3/files/arm-linux-androideabi/lib/python3.6/site-packages/flask/app.py", line 1813, in full_dispatch_request
    rv = self.dispatch_request()
  File "/data/user/0/ru.iiec.pydroid3/files/arm-linux-androideabi/lib/python3.6/site-packages/flask/app.py", line 1799, in dispatch_request
    return self.view_functions[rule.endpoint](**req.view_args)
  File "/data/user/0/ru.iiec.pydroid3/files/arm-linux-androideabi/lib/python3.6/site-packages/flask_login/utils.py", line 261, in decorated_view
    return func(*args, **kwargs)
  File "/storage/emulated/0/Download/blog/app/routers.py", line 64, in follow
    current_user.follow(user)
  File "/storage/emulated/0/Download/blog/app/models.py", line 47, in follow
    if not self.is_following(user):
  File "/storage/emulated/0/Download/blog/app/models.py", line 56, in is_following
    followers.c.followed_id==user).count() > 0
  File "/data/user/0/ru.iiec.pydroid3/files/arm-linux-androideabi/lib/python3.6/site-packages/sqlalchemy/orm/query.py", line 3170, in count
    return self.from_self(col).scalar()
  File "/data/user/0/ru.iiec.pydroid3/files/arm-linux-androideabi/lib/python3.6/site-packages/sqlalchemy/orm/query.py", line 2923, in scalar
    ret = self.one()
  File "/data/user/0/ru.iiec.pydroid3/files/arm-linux-androideabi/lib/python3.6/site-packages/sqlalchemy/orm/query.py", line 2894, in one
    ret = self.one_or_none()
  File "/data/user/0/ru.iiec.pydroid3/files/arm-linux-androideabi/lib/python3.6/site-packages/sqlalchemy/orm/query.py", line 2864, in one_or_none
    ret = list(self)
  File "/data/user/0/ru.iiec.pydroid3/files/arm-linux-androideabi/lib/python3.6/site-packages/sqlalchemy/orm/query.py", line 2935, in __iter__
    return self._execute_and_instances(context)
  File "/data/user/0/ru.iiec.pydroid3/files/arm-linux-androideabi/lib/python3.6/site-packages/sqlalchemy/orm/query.py", line 2958, in _execute_and_instances
    result = conn.execute(querycontext.statement, self._params)
  File "/data/user/0/ru.iiec.pydroid3/files/arm-linux-androideabi/lib/python3.6/site-packages/sqlalchemy/engine/base.py", line 948, in execute
    return meth(self, multiparams, params)
  File "/data/user/0/ru.iiec.pydroid3/files/arm-linux-androideabi/lib/python3.6/site-packages/sqlalchemy/sql/elements.py", line 269, in _execute_on_connection
    return connection._execute_clauseelement(self, multiparams, params)
  File "/data/user/0/ru.iiec.pydroid3/files/arm-linux-androideabi/lib/python3.6/site-packages/sqlalchemy/engine/base.py", line 1060, in _execute_clauseelement
    compiled_sql, distilled_params
  File "/data/user/0/ru.iiec.pydroid3/files/arm-linux-androideabi/lib/python3.6/site-packages/sqlalchemy/engine/base.py", line 1200, in _execute_context
    context)
  File "/data/user/0/ru.iiec.pydroid3/files/arm-linux-androideabi/lib/python3.6/site-packages/sqlalchemy/engine/base.py", line 1413, in _handle_dbapi_exception
    exc_info
  File "/data/user/0/ru.iiec.pydroid3/files/arm-linux-androideabi/lib/python3.6/site-packages/sqlalchemy/util/compat.py", line 203, in raise_from_cause
    reraise(type(exception), exception, tb=exc_tb, cause=cause)
  File "/data/user/0/ru.iiec.pydroid3/files/arm-linux-androideabi/lib/python3.6/site-packages/sqlalchemy/util/compat.py", line 186, in reraise
    raise value.with_traceback(tb)
  File "/data/user/0/ru.iiec.pydroid3/files/arm-linux-androideabi/lib/python3.6/site-packages/sqlalchemy/engine/base.py", line 1193, in _execute_context
    context)
  File "/data/user/0/ru.iiec.pydroid3/files/arm-linux-androideabi/lib/python3.6/site-packages/sqlalchemy/engine/default.py", line 508, in do_execute
    cursor.execute(statement, parameters)
sqlalchemy.exc.OperationalError: (sqlite3.OperationalError) only a single result allowed for a SELECT that is part of an expression [SQL: 'SELECT count(*) AS count_1 \nFROM (SELECT user.id AS user_id, user.username AS user_username, user.email AS user_email, user.password_hash AS user_password_hash, user.about_me AS user_about_me, user.last_seen AS user_last_seen \nFROM user, followers \nWHERE followers.follower_id = ? AND followers.followed_id = user.id AND followers.followed_id = (SELECT user.id AS user_id, user.username AS user_username, user.email AS user_email, user.password_hash AS user_password_hash, user.about_me AS user_about_me, user.last_seen AS user_last_seen \nFROM user \nWHERE user.username = ?)) AS anon_1'] [parameters: (1, 'nelly')] (Background on this error at: http://sqlalche.me/e/e3q8)
2018-07-12 17:26:12,426 INFO: Microblog startup [in /storage/emulated/0/Download/blog/app/__init__.py:33]
2018-07-12 17:26:15,548 ERROR: Exception on /follow/nelly [GET] [in /data/user/0/ru.iiec.pydroid3/files/arm-linux-androideabi/lib/python3.6/site-packages/flask/app.py:1761]
Traceback (most recent call last):
  File "/data/user/0/ru.iiec.pydroid3/files/arm-linux-androideabi/lib/python3.6/site-packages/flask/app.py", line 2292, in wsgi_app
    response = self.full_dispatch_request()
  File "/data/user/0/ru.iiec.pydroid3/files/arm-linux-androideabi/lib/python3.6/site-packages/flask/app.py", line 1815, in full_dispatch_request
    rv = self.handle_user_exception(e)
  File "/data/user/0/ru.iiec.pydroid3/files/arm-linux-androideabi/lib/python3.6/site-packages/flask/app.py", line 1718, in handle_user_exception
    reraise(exc_type, exc_value, tb)
  File "/data/user/0/ru.iiec.pydroid3/files/arm-linux-androideabi/lib/python3.6/site-packages/flask/_compat.py", line 35, in reraise
    raise value
  File "/data/user/0/ru.iiec.pydroid3/files/arm-linux-androideabi/lib/python3.6/site-packages/flask/app.py", line 1813, in full_dispatch_request
    rv = self.dispatch_request()
  File "/data/user/0/ru.iiec.pydroid3/files/arm-linux-androideabi/lib/python3.6/site-packages/flask/app.py", line 1799, in dispatch_request
    return self.view_functions[rule.endpoint](**req.view_args)
  File "/data/user/0/ru.iiec.pydroid3/files/arm-linux-androideabi/lib/python3.6/site-packages/flask_login/utils.py", line 261, in decorated_view
    return func(*args, **kwargs)
  File "/storage/emulated/0/Download/blog/app/routers.py", line 64, in follow
    current_user.follow(user)
  File "/storage/emulated/0/Download/blog/app/models.py", line 47, in follow
    if not self.is_following(user):
  File "/storage/emulated/0/Download/blog/app/models.py", line 56, in is_following
    followers.c.followed_id==user.id).count() > 0
AttributeError: 'BaseQuery' object has no attribute 'id'
2018-07-12 17:29:35,125 INFO: Microblog startup [in /storage/emulated/0/Download/blog/app/__init__.py:33]
2018-07-12 17:29:41,817 INFO: Microblog startup [in /storage/emulated/0/Download/blog/app/__init__.py:33]
2018-07-12 17:29:49,838 INFO: Microblog startup [in /storage/emulated/0/Download/blog/app/__init__.py:33]
2018-07-12 17:30:20,372 INFO: Microblog startup [in /storage/emulated/0/Download/blog/app/__init__.py:33]
